[14/Jul/2022 23:59:25.049]INFO [django.utils.autoreload:637] Watching for file changes with StatReloader
[14/Jul/2022 23:59:46.103]INFO [django.server:161] "GET /admin/ HTTP/1.1" 200 8246
[14/Jul/2022 23:59:46.460]INFO [django.server:161] "GET /staticfiles/admin/css/nav_sidebar.css HTTP/1.1" 200 2271
[14/Jul/2022 23:59:46.460]INFO [django.server:161] "GET /staticfiles/admin/js/nav_sidebar.js HTTP/1.1" 304 0
[14/Jul/2022 23:59:46.461]INFO [django.server:161] "GET /staticfiles/admin/css/dashboard.css HTTP/1.1" 200 380
[14/Jul/2022 23:59:46.461]INFO [django.server:161] "GET /staticfiles/admin/css/base.css HTTP/1.1" 200 19513
[14/Jul/2022 23:59:46.461]INFO [django.server:161] "GET /staticfiles/admin/css/responsive.css HTTP/1.1" 200 18545
[14/Jul/2022 23:59:46.476]INFO [django.server:161] "GET /staticfiles/admin/css/fonts.css HTTP/1.1" 200 423
[14/Jul/2022 23:59:46.489]INFO [django.server:161] "GET /staticfiles/admin/img/icon-addlink.svg HTTP/1.1" 200 331
[14/Jul/2022 23:59:46.489]INFO [django.server:161] "GET /staticfiles/admin/img/icon-changelink.svg HTTP/1.1" 200 380
[14/Jul/2022 23:59:46.498]INFO [django.server:161] "GET /staticfiles/admin/fonts/Roboto-Regular-webfont.woff HTTP/1.1" 200 85876
[14/Jul/2022 23:59:46.499]INFO [django.server:161] "GET /staticfiles/admin/fonts/Roboto-Light-webfont.woff HTTP/1.1" 200 85692
[14/Jul/2022 23:59:46.505]INFO [django.server:161] "GET /staticfiles/admin/fonts/Roboto-Bold-webfont.woff HTTP/1.1" 200 86184
[15/Jul/2022 00:09:32.025]ERROR [django.request:224] Internal Server Error: /api/v1/user/profile/personal
Traceback (most recent call last):
  File "/usr/local/lib/python3.9/site-packages/django/core/handlers/exception.py", line 47, in inner
    response = get_response(request)
  File "/usr/local/lib/python3.9/site-packages/django/core/handlers/base.py", line 204, in _get_response
    response = response.render()
  File "/usr/local/lib/python3.9/site-packages/django/template/response.py", line 105, in render
    self.content = self.rendered_content
  File "/usr/local/lib/python3.9/site-packages/rest_framework/response.py", line 70, in rendered_content
    ret = renderer.render(self.data, accepted_media_type, context)
  File "/usr/local/lib/python3.9/site-packages/rest_framework/renderers.py", line 100, in render
    ret = json.dumps(
  File "/usr/local/lib/python3.9/site-packages/rest_framework/utils/json.py", line 25, in dumps
    return json.dumps(*args, **kwargs)
  File "/usr/local/lib/python3.9/json/__init__.py", line 234, in dumps
    return cls(
  File "/usr/local/lib/python3.9/json/encoder.py", line 199, in encode
    chunks = self.iterencode(o, _one_shot=True)
  File "/usr/local/lib/python3.9/json/encoder.py", line 257, in iterencode
    return _iterencode(o, 0)
  File "/usr/local/lib/python3.9/site-packages/rest_framework/utils/encoders.py", line 67, in default
    return super().default(obj)
  File "/usr/local/lib/python3.9/json/encoder.py", line 179, in default
    raise TypeError(f'Object of type {o.__class__.__name__} '
TypeError: Object of type MultiValueDictKeyError is not JSON serializable
[15/Jul/2022 00:09:32.347]WARNING [django.request:224] Bad Request: /api/v1/user
[15/Jul/2022 00:09:32.654]WARNING [django.request:224] Bad Request: /api/v1/user
[15/Jul/2022 00:10:17.920]ERROR [django.request:224] Internal Server Error: /api/v1/user/profile/personal
Traceback (most recent call last):
  File "/usr/local/lib/python3.9/site-packages/django/core/handlers/exception.py", line 47, in inner
    response = get_response(request)
  File "/usr/local/lib/python3.9/site-packages/django/core/handlers/base.py", line 204, in _get_response
    response = response.render()
  File "/usr/local/lib/python3.9/site-packages/django/template/response.py", line 105, in render
    self.content = self.rendered_content
  File "/usr/local/lib/python3.9/site-packages/rest_framework/response.py", line 70, in rendered_content
    ret = renderer.render(self.data, accepted_media_type, context)
  File "/usr/local/lib/python3.9/site-packages/rest_framework/renderers.py", line 100, in render
    ret = json.dumps(
  File "/usr/local/lib/python3.9/site-packages/rest_framework/utils/json.py", line 25, in dumps
    return json.dumps(*args, **kwargs)
  File "/usr/local/lib/python3.9/json/__init__.py", line 234, in dumps
    return cls(
  File "/usr/local/lib/python3.9/json/encoder.py", line 199, in encode
    chunks = self.iterencode(o, _one_shot=True)
  File "/usr/local/lib/python3.9/json/encoder.py", line 257, in iterencode
    return _iterencode(o, 0)
  File "/usr/local/lib/python3.9/site-packages/rest_framework/utils/encoders.py", line 67, in default
    return super().default(obj)
  File "/usr/local/lib/python3.9/json/encoder.py", line 179, in default
    raise TypeError(f'Object of type {o.__class__.__name__} '
TypeError: Object of type MultiValueDictKeyError is not JSON serializable
[15/Jul/2022 00:10:18.241]WARNING [django.request:224] Bad Request: /api/v1/user
[15/Jul/2022 00:10:18.544]WARNING [django.request:224] Bad Request: /api/v1/user
[15/Jul/2022 00:11:07.908]WARNING [django.request:224] Bad Request: /api/v1/user
[15/Jul/2022 00:11:08.216]WARNING [django.request:224] Bad Request: /api/v1/user
[15/Jul/2022 00:11:54.941]WARNING [django.request:224] Bad Request: /api/v1/user
[15/Jul/2022 00:11:55.261]WARNING [django.request:224] Bad Request: /api/v1/user
[15/Jul/2022 00:12:28.359]WARNING [django.request:224] Bad Request: /api/v1/user
[15/Jul/2022 00:12:28.666]WARNING [django.request:224] Bad Request: /api/v1/user
[15/Jul/2022 00:13:08.258]WARNING [django.request:224] Bad Request: /api/v1/user
[15/Jul/2022 00:13:08.578]WARNING [django.request:224] Bad Request: /api/v1/user
[15/Jul/2022 00:16:02.465]ERROR [django.request:224] Internal Server Error: /api/v1/user/profile/personal
Traceback (most recent call last):
  File "/usr/local/lib/python3.9/site-packages/django/db/models/fields/__init__.py", line 1823, in get_prep_value
    return int(value)
ValueError: invalid literal for int() with base 10: 'one'

The above exception was the direct cause of the following exception:

Traceback (most recent call last):
  File "/usr/src/app/profiles/personal.py", line 32, in create
    countries = Country.objects.get(id=request.data.get("countries"))
  File "/usr/local/lib/python3.9/site-packages/django/db/models/manager.py", line 85, in manager_method
    return getattr(self.get_queryset(), name)(*args, **kwargs)
  File "/usr/local/lib/python3.9/site-packages/django/db/models/query.py", line 424, in get
    clone = self._chain() if self.query.combinator else self.filter(*args, **kwargs)
  File "/usr/local/lib/python3.9/site-packages/django/db/models/query.py", line 941, in filter
    return self._filter_or_exclude(False, args, kwargs)
  File "/usr/local/lib/python3.9/site-packages/django/db/models/query.py", line 961, in _filter_or_exclude
    clone._filter_or_exclude_inplace(negate, args, kwargs)
  File "/usr/local/lib/python3.9/site-packages/django/db/models/query.py", line 968, in _filter_or_exclude_inplace
    self._query.add_q(Q(*args, **kwargs))
  File "/usr/local/lib/python3.9/site-packages/django/db/models/sql/query.py", line 1393, in add_q
    clause, _ = self._add_q(q_object, self.used_aliases)
  File "/usr/local/lib/python3.9/site-packages/django/db/models/sql/query.py", line 1412, in _add_q
    child_clause, needed_inner = self.build_filter(
  File "/usr/local/lib/python3.9/site-packages/django/db/models/sql/query.py", line 1347, in build_filter
    condition = self.build_lookup(lookups, col, value)
  File "/usr/local/lib/python3.9/site-packages/django/db/models/sql/query.py", line 1193, in build_lookup
    lookup = lookup_class(lhs, rhs)
  File "/usr/local/lib/python3.9/site-packages/django/db/models/lookups.py", line 25, in __init__
    self.rhs = self.get_prep_lookup()
  File "/usr/local/lib/python3.9/site-packages/django/db/models/lookups.py", line 77, in get_prep_lookup
    return self.lhs.output_field.get_prep_value(self.rhs)
  File "/usr/local/lib/python3.9/site-packages/django/db/models/fields/__init__.py", line 1825, in get_prep_value
    raise e.__class__(
ValueError: Field 'id' expected a number but got 'one'.

During handling of the above exception, another exception occurred:

Traceback (most recent call last):
  File "/usr/local/lib/python3.9/site-packages/django/core/handlers/exception.py", line 47, in inner
    response = get_response(request)
  File "/usr/local/lib/python3.9/site-packages/django/core/handlers/base.py", line 181, in _get_response
    response = wrapped_callback(request, *callback_args, **callback_kwargs)
  File "/usr/local/lib/python3.9/site-packages/django/views/decorators/csrf.py", line 54, in wrapped_view
    return view_func(*args, **kwargs)
  File "/usr/local/lib/python3.9/site-packages/rest_framework/viewsets.py", line 125, in view
    return self.dispatch(request, *args, **kwargs)
  File "/usr/local/lib/python3.9/site-packages/rest_framework/views.py", line 509, in dispatch
    response = self.handle_exception(exc)
  File "/usr/local/lib/python3.9/site-packages/rest_framework/views.py", line 469, in handle_exception
    self.raise_uncaught_exception(exc)
  File "/usr/local/lib/python3.9/site-packages/rest_framework/views.py", line 480, in raise_uncaught_exception
    raise exc
  File "/usr/local/lib/python3.9/site-packages/rest_framework/views.py", line 506, in dispatch
    response = handler(request, *args, **kwargs)
  File "/usr/src/app/profiles/personal.py", line 43, in create
    {"data": False, "msg": f"{err}"}, status=status.HTT_400_BAD_REQUEST
AttributeError: module 'rest_framework.status' has no attribute 'HTT_400_BAD_REQUEST'
[15/Jul/2022 00:16:02.746]WARNING [django.request:224] Bad Request: /api/v1/user
[15/Jul/2022 00:16:03.103]WARNING [django.request:224] Bad Request: /api/v1/user
[15/Jul/2022 00:16:32.537]ERROR [django.request:224] Internal Server Error: /api/v1/user/profile/personal
Traceback (most recent call last):
  File "/usr/local/lib/python3.9/site-packages/django/core/handlers/exception.py", line 47, in inner
    response = get_response(request)
  File "/usr/local/lib/python3.9/site-packages/django/core/handlers/base.py", line 204, in _get_response
    response = response.render()
  File "/usr/local/lib/python3.9/site-packages/django/template/response.py", line 105, in render
    self.content = self.rendered_content
  File "/usr/local/lib/python3.9/site-packages/rest_framework/response.py", line 70, in rendered_content
    ret = renderer.render(self.data, accepted_media_type, context)
  File "/usr/local/lib/python3.9/site-packages/rest_framework/renderers.py", line 100, in render
    ret = json.dumps(
  File "/usr/local/lib/python3.9/site-packages/rest_framework/utils/json.py", line 25, in dumps
    return json.dumps(*args, **kwargs)
  File "/usr/local/lib/python3.9/json/__init__.py", line 234, in dumps
    return cls(
  File "/usr/local/lib/python3.9/json/encoder.py", line 199, in encode
    chunks = self.iterencode(o, _one_shot=True)
  File "/usr/local/lib/python3.9/json/encoder.py", line 257, in iterencode
    return _iterencode(o, 0)
  File "/usr/local/lib/python3.9/site-packages/rest_framework/utils/encoders.py", line 67, in default
    return super().default(obj)
  File "/usr/local/lib/python3.9/json/encoder.py", line 179, in default
    raise TypeError(f'Object of type {o.__class__.__name__} '
TypeError: Object of type MultiValueDictKeyError is not JSON serializable
[15/Jul/2022 00:16:32.833]WARNING [django.request:224] Bad Request: /api/v1/user
[15/Jul/2022 00:16:33.185]WARNING [django.request:224] Bad Request: /api/v1/user
[15/Jul/2022 00:20:36.410]ERROR [django.request:224] Internal Server Error: /api/v1/user/profile/personal
Traceback (most recent call last):
  File "/usr/local/lib/python3.9/site-packages/django/core/handlers/exception.py", line 47, in inner
    response = get_response(request)
  File "/usr/local/lib/python3.9/site-packages/django/core/handlers/base.py", line 204, in _get_response
    response = response.render()
  File "/usr/local/lib/python3.9/site-packages/django/template/response.py", line 105, in render
    self.content = self.rendered_content
  File "/usr/local/lib/python3.9/site-packages/rest_framework/response.py", line 70, in rendered_content
    ret = renderer.render(self.data, accepted_media_type, context)
  File "/usr/local/lib/python3.9/site-packages/rest_framework/renderers.py", line 100, in render
    ret = json.dumps(
  File "/usr/local/lib/python3.9/site-packages/rest_framework/utils/json.py", line 25, in dumps
    return json.dumps(*args, **kwargs)
  File "/usr/local/lib/python3.9/json/__init__.py", line 234, in dumps
    return cls(
  File "/usr/local/lib/python3.9/json/encoder.py", line 199, in encode
    chunks = self.iterencode(o, _one_shot=True)
  File "/usr/local/lib/python3.9/json/encoder.py", line 257, in iterencode
    return _iterencode(o, 0)
  File "/usr/local/lib/python3.9/site-packages/rest_framework/utils/encoders.py", line 67, in default
    return super().default(obj)
  File "/usr/local/lib/python3.9/json/encoder.py", line 179, in default
    raise TypeError(f'Object of type {o.__class__.__name__} '
TypeError: Object of type MultiValueDictKeyError is not JSON serializable
[15/Jul/2022 00:20:36.680]WARNING [django.request:224] Bad Request: /api/v1/user
[15/Jul/2022 00:20:37.021]WARNING [django.request:224] Bad Request: /api/v1/user
[15/Jul/2022 00:22:44.000]INFO [django.utils.autoreload:251] /usr/src/app/core/profile.py changed, reloading.
[15/Jul/2022 00:22:44.842]INFO [django.utils.autoreload:637] Watching for file changes with StatReloader
[15/Jul/2022 00:23:27.077]INFO [django.server:161] "GET /admin/core/personalprofile/ HTTP/1.1" 200 9605
[15/Jul/2022 00:23:27.138]INFO [django.server:161] "GET /staticfiles/admin/css/changelists.css HTTP/1.1" 200 6874
[15/Jul/2022 00:23:27.144]INFO [django.server:161] "GET /staticfiles/admin/js/jquery.init.js HTTP/1.1" 200 347
[15/Jul/2022 00:23:27.144]INFO [django.server:161] "GET /staticfiles/admin/js/actions.js HTTP/1.1" 200 7664
[15/Jul/2022 00:23:27.148]INFO [django.server:161] "GET /admin/jsi18n/ HTTP/1.1" 200 3195
[15/Jul/2022 00:23:27.149]INFO [django.server:161] "GET /staticfiles/admin/js/core.js HTTP/1.1" 200 5698
[15/Jul/2022 00:23:27.150]INFO [django.server:161] "GET /staticfiles/admin/js/admin/RelatedObjectLookups.js HTTP/1.1" 200 5984
[15/Jul/2022 00:23:27.150]INFO [django.server:161] "GET /staticfiles/admin/js/urlify.js HTTP/1.1" 200 7902
[15/Jul/2022 00:23:27.151]INFO [django.server:161] "GET /staticfiles/admin/js/prepopulate.js HTTP/1.1" 200 1531
[15/Jul/2022 00:23:27.152]INFO [django.server:161] "GET /staticfiles/admin/js/vendor/jquery/jquery.js HTTP/1.1" 200 287630
[15/Jul/2022 00:23:27.153]INFO [django.server:161] "GET /staticfiles/admin/js/vendor/xregexp/xregexp.js HTTP/1.1" 200 232381
[15/Jul/2022 00:23:27.189]INFO [django.server:161] "GET /staticfiles/admin/img/tooltag-add.svg HTTP/1.1" 200 331
[15/Jul/2022 00:23:28.852]INFO [django.server:161] "GET /admin/core/personalprofile/1/change/ HTTP/1.1" 200 20930
[15/Jul/2022 00:23:28.922]INFO [django.server:161] "GET /staticfiles/admin/js/calendar.js HTTP/1.1" 200 8466
[15/Jul/2022 00:23:28.923]INFO [django.server:161] "GET /staticfiles/admin/js/prepopulate_init.js HTTP/1.1" 200 492
[15/Jul/2022 00:23:28.924]INFO [django.server:161] "GET /staticfiles/admin/js/change_form.js HTTP/1.1" 200 606
[15/Jul/2022 00:23:28.924]INFO [django.server:161] "GET /staticfiles/admin/css/forms.css HTTP/1.1" 200 8804
[15/Jul/2022 00:23:28.924]INFO [django.server:161] "GET /staticfiles/admin/js/admin/DateTimeShortcuts.js HTTP/1.1" 200 19634
[15/Jul/2022 00:23:28.926]INFO [django.server:161] "GET /admin/jsi18n/ HTTP/1.1" 200 3195
[15/Jul/2022 00:23:28.941]INFO [django.server:161] "GET /staticfiles/admin/css/widgets.css HTTP/1.1" 200 11097
[15/Jul/2022 00:23:29.004]INFO [django.server:161] "GET /staticfiles/admin/img/icon-calendar.svg HTTP/1.1" 200 1086
[15/Jul/2022 00:24:14.962]INFO [django.utils.autoreload:251] /usr/src/app/core/profile.py changed, reloading.
[15/Jul/2022 00:24:15.658]INFO [django.utils.autoreload:637] Watching for file changes with StatReloader
[15/Jul/2022 00:34:49.844]INFO [django.utils.autoreload:251] /usr/src/app/core/profile.py changed, reloading.
[15/Jul/2022 00:34:50.522]INFO [django.utils.autoreload:637] Watching for file changes with StatReloader
[15/Jul/2022 00:39:25.280]INFO [django.utils.autoreload:251] /usr/src/app/core/profile.py changed, reloading.
[15/Jul/2022 00:39:25.957]INFO [django.utils.autoreload:637] Watching for file changes with StatReloader
[15/Jul/2022 00:40:32.646]INFO [django.utils.autoreload:251] /usr/src/app/core/profile.py changed, reloading.
[15/Jul/2022 00:40:33.322]INFO [django.utils.autoreload:637] Watching for file changes with StatReloader
[15/Jul/2022 00:43:07.827]INFO [django.utils.autoreload:251] /usr/src/app/core/profile.py changed, reloading.
[15/Jul/2022 00:43:08.503]INFO [django.utils.autoreload:637] Watching for file changes with StatReloader
[15/Jul/2022 00:48:08.935]INFO [django.utils.autoreload:251] /usr/src/app/profiles/personal.py changed, reloading.
[15/Jul/2022 00:48:09.613]INFO [django.utils.autoreload:637] Watching for file changes with StatReloader
[15/Jul/2022 00:48:47.314]ERROR [django.request:224] Internal Server Error: /api/v1/user/profile/personal
Traceback (most recent call last):
  File "/usr/src/app/profiles/personal.py", line 44, in create
    prof_personal = PersonalProfile.created(request)
NameError: name 'PersonalProfile' is not defined

During handling of the above exception, another exception occurred:

Traceback (most recent call last):
  File "/usr/local/lib/python3.9/site-packages/django/core/handlers/exception.py", line 47, in inner
    response = get_response(request)
  File "/usr/local/lib/python3.9/site-packages/django/core/handlers/base.py", line 181, in _get_response
    response = wrapped_callback(request, *callback_args, **callback_kwargs)
  File "/usr/local/lib/python3.9/site-packages/django/views/decorators/csrf.py", line 54, in wrapped_view
    return view_func(*args, **kwargs)
  File "/usr/local/lib/python3.9/site-packages/rest_framework/viewsets.py", line 125, in view
    return self.dispatch(request, *args, **kwargs)
  File "/usr/local/lib/python3.9/site-packages/rest_framework/views.py", line 509, in dispatch
    response = self.handle_exception(exc)
  File "/usr/local/lib/python3.9/site-packages/rest_framework/views.py", line 469, in handle_exception
    self.raise_uncaught_exception(exc)
  File "/usr/local/lib/python3.9/site-packages/rest_framework/views.py", line 480, in raise_uncaught_exception
    raise exc
  File "/usr/local/lib/python3.9/site-packages/rest_framework/views.py", line 506, in dispatch
    response = handler(request, *args, **kwargs)
  File "/usr/src/app/profiles/personal.py", line 51, in create
    {"data": False, "msg": f"{err}"}, status=status.HTT_400_BAD_REQUEST
AttributeError: module 'rest_framework.status' has no attribute 'HTT_400_BAD_REQUEST'
[15/Jul/2022 00:48:47.537]WARNING [django.request:224] Bad Request: /api/v1/user
[15/Jul/2022 00:48:47.819]WARNING [django.request:224] Bad Request: /api/v1/user
[15/Jul/2022 00:49:17.256]INFO [django.utils.autoreload:251] /usr/src/app/profiles/personal.py changed, reloading.
[15/Jul/2022 00:49:17.928]INFO [django.utils.autoreload:637] Watching for file changes with StatReloader
[15/Jul/2022 00:49:23.514]WARNING [django.request:224] Bad Request: /api/v1/user/profile/personal
[15/Jul/2022 00:49:23.734]WARNING [django.request:224] Bad Request: /api/v1/user
[15/Jul/2022 00:49:24.021]WARNING [django.request:224] Bad Request: /api/v1/user
